<?xml version="1.0" encoding="utf-8"?>
<!-- This URDF was automatically created by SolidWorks to URDF Exporter! Originally created by Stephen Brawner (brawner@gmail.com) 
     Commit Version: 1.6.0-4-g7f85cfe  Build Version: 1.6.7995.38578
     For more information, please see http://wiki.ros.org/sw_urdf_exporter -->
<robot
  name="gantry">
  
  <link name="world"/>
  <joint
    name="base_joint"
    type="fixed">
    <parent
      link="world" />
    <child
      link="base_link_inertia" />
    <origin rpy="0 0 0" xyz="0.0 0.0 0.0"/>
  </joint>
  <link
    name="base_link_inertia">
    <inertial>
      <origin
        xyz="0.00034882 0.032516 0.24303"
        rpy="0 0 0" />
      <mass
        value="10" />
      <inertia
        ixx="0.12532"
        ixy="-3.6303E-09"
        ixz="8.8835E-07"
        iyy="0.041971"
        iyz="-4.7939E-07"
        izz="0.13107" />
    </inertial>
    <visual>
      <origin
        xyz="0 0 0"
        rpy="0 0 0" />
      <geometry>
        <mesh
          filename="package://gantry_description/meshes/gantry/set4/visual/base_link.stl" scale="0.001  0.001 0.001" />
      </geometry>
      <material
        name="">
        <color
          rgba="0.79216 0.81961 0.93333 1" />
      </material>
    </visual>
    <collision>
      <origin
        xyz="0 0 0"
        rpy="0 0 0" />
      <geometry>
        <mesh
          filename="package://gantry_description/meshes/gantry/set4/collision/base_link.dae" scale="0.001  0.001 0.001" />
      </geometry>
    </collision>
  </link>
  <link
    name="x_link">
    <inertial>
      <origin
        xyz="-0.048186 0.050712 0.0022474"
        rpy="0 0 0" />
      <mass
        value="1.6" />
      <inertia
        ixx="0.00043215"
        ixy="1.9114E-09"
        ixz="2.3613E-07"
        iyy="0.011891"
        iyz="2.7571E-05"
        izz="0.01197" />
    </inertial>
    <visual>
      <origin
        xyz="0 0 0"
        rpy="0 0 0" />
      <geometry>
        <mesh
          filename="package://gantry_description/meshes/gantry/set4/visual/x_link.stl" scale="0.001  0.001 0.001" />
      </geometry>
      <material
        name="">
        <color
          rgba="0.79216 0.81961 0.93333 1" />
      </material>
    </visual>
    <collision>
      <origin
        xyz="0 0 0"
        rpy="0 0 0" />
      <geometry>
        <mesh
          filename="package://gantry_description/meshes/gantry/set4/collision/x_link.dae" scale="0.001  0.001 0.001" />
      </geometry>
    </collision>
  </link>
  <joint
    name="x_joint"
    type="prismatic">
    <origin
      xyz="0 0.05 0.45"
      rpy="1.5708 -2.0964E-05 0" />
    <parent
      link="base_link_inertia" />
    <child
      link="x_link" />
    <axis
      xyz="0 0 -1" />
    <limit
      lower="-0.17"
      upper="0.17"
      effort="100"
      velocity="1" />
  </joint>
  <link
    name="y_link">
    <inertial>
      <origin
        xyz="-0.11023 -0.047388 0.010097"
        rpy="0 0 0" />
      <mass
        value="1" />
      <inertia
        ixx="0.00027954"
        ixy="3.1449E-07"
        ixz="1.1171E-08"
        iyy="0.0072125"
        iyz="4.0095E-07"
        izz="0.0071657" />
    </inertial>
    <visual>
      <origin
        xyz="0 0 0"
        rpy="0 0 0" />
      <geometry>
        <mesh
          filename="package://gantry_description/meshes/gantry/set4/visual/y_link.stl" scale="0.001  0.001 0.001" />
      </geometry>
      <material
        name="">
        <color
          rgba="0.79216 0.81961 0.93333 1" />
      </material>
    </visual>
    <collision>
      <origin
        xyz="0 0 0"
        rpy="0 0 0" />
      <geometry>
        <mesh
          filename="package://gantry_description/meshes/gantry/set4/collision/y_link.dae" scale="0.001  0.001 0.001" />
      </geometry>
    </collision>
  </link>
  <joint
    name="y_joint"
    type="prismatic">
    <origin
      xyz="-0.01 0.053 0.0295"
      rpy="-1.5708 0 -1.5708" />
    <parent
      link="x_link" />
    <child
      link="y_link" />
    <axis
      xyz="0 0 1" />
    <limit
      lower="-0.16"
      upper="0.16"
      effort="100"
      velocity="1" />
  </joint>
  <link
    name="z_link">
    <inertial>
      <origin
        xyz="6.1912E-08 0.0017903 -0.037699"
        rpy="0 0 0" />
      <mass
        value="0.12177" />
      <inertia
        ixx="4.7832E-05"
        ixy="4.813E-11"
        ixz="5.2651E-11"
        iyy="5.6754E-05"
        iyz="4.1076E-07"
        izz="3.9828E-05" />
    </inertial>
    <visual>
      <origin
        xyz="0 0 0"
        rpy="0 0 0" />
      <geometry>
        <mesh
          filename="package://gantry_description/meshes/gantry/set4/visual/z_link.stl" scale="0.001  0.001 0.001" />
      </geometry>
      <material
        name="">
        <color
          rgba="0.79216 0.81961 0.93333 1" />
      </material>
    </visual>
    <collision>
      <origin
        xyz="0 0 0"
        rpy="0 0 0" />
      <geometry>
        <mesh
          filename="package://gantry_description/meshes/gantry/set4/collision/z_link.dae" scale="0.001  0.001 0.001" />
      </geometry>
    </collision>
  </link>
  <joint
    name="z_joint"
    type="prismatic">
    <origin
      xyz="0.2 -0.081053 0.011"
      rpy="0 1.5708 0" />
    <parent
      link="y_link" />
    <child
      link="z_link" />
    <axis
      xyz="0 0 -1" />
    <limit
      lower="0"
      upper="0.35"
      effort="100"
      velocity="1" />
  </joint>

</robot>